model
name = bankhub
size = 160 40 160
scale = 0.05
origin = -y
material type = toon, lighting = smooth, deform = 1 1 
  colors = A:#EEE B:#777 C:#444
voxels
51-11A40-9A99-5(11A40-9A100-)5A3C3A40-2A4C3A4(100-5A3C3A40-9A)2(100-11A40-5A4B)4(100-3C8A40-5A4B)3(100-6A3B2A40-9A)3(100-11A40-9A)3(100-A4C6A40-2A3C4A)4(100-11A40-9A)2(100-4B7A40-9A)100-4B7A2(40-5A4B100-11A)40-9A3(100-11A40-A3C5A)2(100-11A40-9A)5(100-60A)100-15A5B40A2(100-4A4C7A5B14A3B23A)100-4A4C26A3B23A100-4A4C38A2(4C4A3B3A100-27A6C13A)4C4A3B3A100-46A4C10A2(100-37A6B17A)100-8A5B24A6B17A100-8A5B4A5C15A6B17A100-8A5B4A5C38A100-17A5C38A100-60A100-12A2C46A2(100-12A2C15A5B6A5C15A)100-29A5B19A4B3A100-53A4B3A100-4A3C53A100-4A3C14A2C37A2(100-4A3C36A3B14A)2(100-18A7B35A)2(100-18A7B8A5C22A)100-44A2B14A100-10A4C30A2B14A100-10A4C42A2(4C100-56A)4C2(100-60A)99-35(A60-A98-)3(A60-C98-)A60-A98-A60-A97-39(A62-A96-)A62-A95-39(A64-A94-)A64-A93-21(A66-A92-)A66-B92-A66-A92-C5(66-A92-A)2(66-A92-C)2(66-B92-C)3(66-B92-A)4(66-A92-A)66-A91-6(A68-A90-)4(C68-A90-)13(A68-A90-)C5(68-A90-A)2(68-A90-C)2(68-B90-C)68-B90-A2(68-B90-B)68-A90-B3(68-A90-A)68-A89-6(A70-A88-)4(C70-A88-)5(A70-A88-)3(B70-A88-)11(A70-A88-)C70-A3(88-C70-B)88-A2(70-B88-B)70-A88-B3(70-A88-A)70-A87-6(A72-A86-)4(C72-A86-)5(A72-A86-)3(B72-A86-)12(A72-A86-)4(A72-B86-)B72-B2(86-B72-A)3(86-A72-A)85-6(A74-A84-)4(C74-A84-)24(A74-A84-)3(B74-A84-)2(A74-A84-)A74-A83-6(A76-A82-)4(C76-A82-)3(A76-A82-)4(A76-B82-)3(A76-A82-)2(C76-A82-)3(A76-C82-)9(A76-A82-)3(B76-A82-)2(A76-A82-)A76-A81-13(A78-A80-)4(A78-B80-)3(A78-A80-)2(C78-A80-)3(A78-C80-)A2(78-A80-B)12(78-A80-A)78-A79-13(A80-A78-)4(A80-B78-)9(A80-A78-)2(B80-A78-)11(A80-A78-)A80-A77-8(A82-A76-)5(B82-A76-)4(A82-B76-)9(A82-A76-)2(B82-A76-)7(A82-A76-)3(A82-C76-)A82-A76-A82-A75-8(A84-A74-)5(B84-A74-)2(A84-A74-)2(C84-A74-)7(A84-A74-)4(B84-A74-)2(A84-B74-)5(A84-A74-)3(A84-C74-)A84-A74-A84-A73-6(A86-A72-)2(A86-C72-)B86-C4(72-B86-A)2(72-A86-A)2(72-C86-A)7(72-A86-A)4(72-B86-A)2(72-A86-B)10(72-A86-A)71-4(A88-A70-)2(C88-A70-)2(C88-C70-)A88-C6(70-A88-A)2(70-C88-A)11(70-A88-A)2(70-A88-B)10(70-A88-A)69-4(A90-A68-)2(C90-A68-)2(C90-C68-)A90-C6(68-A90-A)2(68-C90-A)68-A90-A68-A2(90-B68-C)2(90-B68-A)10(90-A68-A)3(90-A68-C)4(90-A68-A)90-A67-6(A92-A66-)3(A92-C66-)9(A92-A66-)A2(92-B66-C)2(92-B66-A)10(92-A66-A)3(92-A66-C)4(92-A66-A)92-A65-6(A94-A64-)3(A94-C64-)9(A94-A64-)A2(94-B64-C)2(94-B64-A)3(94-A64-A)3(94-A64-C)4(94-A64-A)94-A3(64-C94-B)4(64-A94-A)63-6(A96-A62-)3(A96-C62-)9(A96-A62-)4(A96-B62-)4(A96-A62-)3(C96-A62-)4(A96-A62-)3(C96-B62-)3(A96-A62-)A96-A61-26(A98-A60-)3(C98-A60-)4(A98-A60-)3(C98-B60-)3(A98-A60-)A98-A59-33(A100-A58-)3(A100-B58-)3(A100-A58-)A100-A57-21(A102-A56-)3(B102-A56-)15(A102-A56-)A102-A55-12(A104-A54-)4(C104-A54-)3(A104-A54-)2(A104-C54-)3(B104-C54-)A104-C15(54-A104-A)53-4(A106-A52-)4(B106-A52-)4(A106-A52-)4(C106-A52-)3(A106-A52-)2(A106-C52-)3(B106-C52-)A106-C15(52-A106-A)51-4(A108-A50-)4(B108-A50-)4(A108-A50-)4(C108-A50-)3(A108-A50-)6(A108-C50-)7(A108-A50-)3(B108-A50-)4(A108-A50-)A108-A49-4(A110-A48-)4(B110-A48-)4(A110-A48-)4(C110-A48-)3(A110-A48-)6(A110-C48-)7(A110-A48-)3(B110-A48-)A110-A48-A110-C3(48-A110-A)47-32(A112-A46-)3(B112-A46-)A112-A46-A112-C3(46-A112-A)45-24(A114-A44-)6(C114-A44-)2(A114-A44-)3(B114-A44-)A114-A44-A114-C3(44-A114-A)43-2(A116-A42-)A116-B5(42-A116-A)2(42-A116-B)14(42-A116-A)6(42-C116-A)2(42-A116-A)3(42-B116-A)2(42-A116-A)42-C2(116-A42-A)116-A41-8(A118-A40-)2(A118-B40-)13(A118-A40-)A5(118-B40-C)118-A40-C7(118-A40-A)118-A40-C2(118-A40-A)118-A39-8(A120-A38-)2(A120-B38-)13(A120-A38-)A5(120-B38-C)120-A38-C7(120-A38-A)120-A38-C2(120-A38-A)120-A37-8(A122-A36-)2(B122-B36-)B13(122-A36-A)5(122-B36-C)122-A36-C7(122-A36-A)122-A36-C2(122-A36-A)122-A35-8(A124-A34-)2(B124-B34-)B2(124-A34-A)2(124-A34-C)9(124-A34-A)5(124-B34-A)11(124-A34-A)124-A33-8(A126-A32-)3(B126-A32-)2(A126-A32-)2(C126-A32-)3(A126-C32-)5(A126-A32-)2(A126-B32-)2(B126-B32-)A126-B5(32-A126-A)3(32-A126-C)4(32-A126-A)31-8(A128-A30-)3(B128-A30-)4(A128-A30-)3(A128-C30-)7(A128-A30-)2(B128-A30-)6(A128-A30-)3(A128-C30-)3(A128-A30-)A128-A29-15(A130-A28-)3(A130-C28-)7(A130-A28-)2(B130-A28-)6(A130-A28-)A3(130-C28-C)3(130-A28-A)130-A27-25(A132-A26-)2(B132-A26-)6(A132-A26-)A3(132-C26-C)3(132-A26-A)132-A25-6(A134-A24-)B18(134-A24-A)2(134-A24-B)7(134-A24-A)3(134-A24-C)3(134-A24-A)134-A23-12(A136-A22-)4(A136-B22-)18(A136-A22-)3(C136-A22-)2(A136-A22-)A136-A21-12(A138-A20-)4(A138-B20-)23(A138-A20-)A138-A19-12(A140-A18-)4(A140-B18-)15(A140-A18-)2(C140-A18-)6(A140-A18-)A140-A17-6(A142-A16-)6(C142-A16-)3(A142-A16-)5(B142-A16-)11(A142-A16-)2(C142-A16-)3(A142-B16-)3(A142-A16-)A142-A15-6(A144-A14-)6(C144-A14-)3(A144-A14-)5(B144-A14-)2(A144-A14-)3(C144-B14-)3(A144-B14-)5(A144-A14-)3(A144-B14-)3(A144-A14-)A144-A13-6(A146-A12-)6(C146-A12-)3(A146-A12-)5(B146-A12-)2(A146-A12-)3(C146-B12-)3(A146-B12-)5(A146-A12-)2(B146-B12-)A146-B4(12-A146-A)11-16(A148-A10-)4(A148-C10-)2(A148-A10-)3(C148-B10-)3(A148-B10-)5(A148-A10-)2(B148-B10-)A148-B4(10-A148-A)9-16(A150-A8-)4(A150-C8-)2(A150-A8-)3(C150-B8-)3(A150-B8-)5(A150-A8-)2(B150-B8-)A150-B4(8-A150-A)7-16(A152-A6-)4(A152-C6-)2(A152-A6-)3(C152-A6-)8(A152-A6-)2(B152-A6-)4(A152-A6-)A152-A5-16(A154-A4-)4(A154-C4-)2(A154-A4-)3(C154-A4-)14(A154-A4-)A154-A3-16(A156-A2-)4(A156-C2-)19(A156-A2-)A156-A-A16(158-2A)4(158-CA)36(158-2A)4(158-CA)23(158-2A)2(2(158-BA)3(158-BC)158-BA11(158-2A)2(158-AC)9(158-2A)2(158-AB)10(158-2A))6(158-BA)11(158-2A)2(158-AC)158-2A3(158-BA)5(158-2A)2(158-AB)10(158-2A)6(158-BA)3(158-2A)7(158-AB)158-2A2(158-AC)158-2A3(158-BA)4(158-2A)158-CA2(158-CB)158-CA9(158-2A)6(158-BA)3(158-2A)7(158-AB)4(158-2A)3(158-BA)4(158-2A)4(158-CA)9(158-2A)6(158-BA)3(158-2A)7(158-AB)4(158-2A)3(158-BA)158-AC3(158-2A)4(158-CA)9(158-2A)2(6(158-BA)3(158-2A)7(158-AB)11(158-2A)4(158-CA)3(158-BA)6(158-2A))158-2A4(158-AB)22(158-2A)4(158-CA)3(158-BA)2(7(158-2A)4(158-AB)25(158-2A)4(158-BA))4(158-2A)2(158-AC)158-2A4(158-AB)4(158-2A)4(158-AC)9(158-2A)2(158-AC)3(158-2A)3(158-AB)4(158-BA)4(158-2A)2(158-AC)9(158-2A)4(158-AC)8(158-2A)158-CA2(158-2C)158-CA2(158-2A)3(158-AB)4(158-BA)158-AC3(158-2A)2(158-AC)9(158-2A)2(158-AC)2(158-BC)8(158-2A)158-CA2(158-2C)158-CA2(158-2A)3(158-AB)8(158-2A)2(158-AC)9(158-2A)2(158-AC)2(158-BC)8(158-2A)158-CA2(158-2C)158-CA2(158-2A)3(158-AB)2(158-2A)158-AC5(158-2A)2(158-AC)11(158-2A)2(158-BA)8(158-2A)158-CA2(158-2C)158-CA13(158-2A)2(158-AC)2(158-CA)9(158-2A)2(158-BA)8(158-2A)4(158-CA)15(158-2A)2(158-CA)9(158-2A)2(158-BA)27(158-2A)2(158-CA)46(158-2A)2(158-CA)13(158-2A)158-BA18(158-2A)158-AC5(158-2A)2(158-CA)2(158-2A)4(158-AB)7(158-2A)158-BA8(158-2A)158-AC9(158-2A)158-AC5(158-2A)2(158-CA)2(158-2A)4(158-AB)7(158-2A)158-BA24(158-2A)2(158-2C)158-AC158-2A4(158-AB)7(158-2A)158-BA24(158-2A)3(158-AC)9(158-2A)158-AC2(158-2A)158-BA3(158-2A)3(158-AC)18(158-2A)3(158-AC)9(158-2A)158-AC6(158-2A)2(158-AC)158-2C2(158-CA)9(158-2A)2(158-AB)5(158-2A)3(158-AC)9(158-2A)158-AC8(158-2A)3(158-CA)9(158-2A)2(158-AB)5(158-2A)3(158-AC)18(158-2A)3(158-CA)9(158-2A)2(158-AB)26(158-2A)3(158-CA)9(158-2A)2(158-AB)7(158-2A)5(158-BA)26(158-2A)2(158-AB)7(158-2A)4(158-BA)158-2B2(3(158-AB)5(158-2A))23(158-2A)2(4(158-AB)5(158-2A)3(158-AB)4(158-2A)2(158-AC)22(158-2A))4(158-AB)4(158-CA)4(158-2A)4(158-BA)2(158-AC)7(158-2A)4(158-AC)15(158-2A)4(158-CA)4(158-2A)4(158-BA)9(158-2A)2(158-A4(C158-B)A14(158-2A)4(158-CA)4(158-2A)4(158-BA)3(158-2A)158-AC5(158-2A))158-A4(C158-B)A14(158-2A)4(158-CA)4(158-2A)4(158-BA)9(158-2A)158-A4(C158-B)A7(158-2A)3(158-CA)6(158-2A)3(158-AC)3(158-2A)4(158-BA)9(158-2A)158-A4(C158-B)A4(158-2A)2(3(158-AB)158-CB2(158-CA)6(158-2A)3(158-AC)16(158-2A)4(158-AC)158-2A2(158-CA)2(158-2A))4(158-AB)8(158-2A)3(158-AC)5(158-2A)2(158-AB)9(158-2A)4(158-AC)158-2A2(158-CA)2(158-2A)4(158-AB)14(158-2A)3(2(158-CA)2(158-CB)158-CA17(158-2A)4(158-AB)10(158-2A)2(158-BA)2(158-2A))2(158-CA)2(158-CB)158-CA17(158-2A)4(158-AB)2(158-2A)4(158-AC)4(158-2A)2(158-BA)2(158-2A)5(158-CA)17(158-2A)4(158-AB)2(158-BA)158-B3(C158-A)C4(158-2A)2(158-BA)2(158-2A)5(158-CA)21(158-2A)2(158-BA)158-B3(C158-A)C4(158-2A)2(158-BA)28(158-2A)2(158-BA)158-B3(C158-A)C4(158-2A)2(158-BA)21(158-2A)2(2(158-AC)7(158-2A)4(158-AC)13(158-2A)2(158-AC)12(158-2A))2(2(158-AC)33(158-2A)4(158-AB)158-2A)158-AC158-BC20(158-2A)3(158-BA)10(158-2A)4(158-AB)158-2A158-AC158-BC3(9(158-2A)6(158-AB)5(158-2A)3(158-BA)16(158-2A)158-BA)9(158-2A)6(158-AB)5(158-2A)3(158-BA)6(158-2A)158-A-9(A156-A2-)A156-B10(2-A156-A)6(2-B156-A)14(2-A156-A)3-9(A154-A4-)A154-B15(4-A154-A)5(4-B154-A)3(4-A154-A)4(4-C154-A)3(4-A154-A)5-9(A152-A6-)A152-B3(6-A152-A)4(6-C152-A)8(6-A152-A)5(6-B152-A)3(6-A152-A)4(6-C152-A)3(6-A152-A)7-9(A150-A8-)A150-B3(8-A150-A)4(8-C150-A)16(8-A150-A)4(8-C150-A)3(8-A150-A)9-13(A148-A10-)4(C148-A10-)6(A148-A10-)4(A148-C10-)12(A148-A10-)A148-A11-13(A146-A12-)4(C146-A12-)6(A146-A12-)4(A146-C12-)12(A146-A12-)A146-A13-11(A144-A14-)2(A144-C14-)10(A144-A14-)4(A144-C14-)12(A144-A14-)A144-A15-3(A142-A16-)C8(142-A16-A)2(142-C16-A)8(142-A16-A)2(142-B16-A)142-B4(16-C142-A)3(16-A142-A)3(16-A142-B)6(16-A142-A)17-3(A140-A18-)C8(140-A18-A)2(140-C18-A)8(140-A18-A)2(140-B18-A)140-B4(18-C140-A)3(18-A140-A)3(18-A140-B)6(18-A140-A)19-3(A138-A20-)C4(138-A20-A)4(138-A20-B)2(138-C20-A)8(138-A20-A)2(138-B20-A)138-B4(20-C138-A)3(20-A138-A)2(20-A138-B)20-B138-B20-B5(138-A20-A)138-A21-8(A136-A22-)3(B136-A22-)B2(136-C22-A)7(136-A22-A)136-A3(22-B136-B)22-B3(136-A22-C)4(136-A22-A)136-B22-A2(136-B22-B)5(136-A22-A)136-A23-8(A134-A24-)4(B134-A24-)9(A134-A24-)3(B134-B24-)B3(134-A24-C)5(134-A24-A)2(134-A24-B)5(134-A24-A)134-A25-8(A132-A26-)4(B132-A26-)9(A132-A26-)3(B132-B26-)B4(132-A26-A)3(132-C26-A)8(132-A26-A)132-A27-21(A130-A28-)4(B130-A28-)14(A130-A28-)A130-A29-3(A128-A30-)B128-A4(30-A128-B)25(30-A128-A)4(30-C128-A)3(30-A128-A)31-3(A126-A32-)B126-A4(32-A126-B)5(32-A126-A)32-B19(126-A32-A)4(126-A32-C)3(126-A32-A)126-A33-3(A124-A34-)B124-A4(34-A124-B)5(34-A124-A)34-B6(124-A34-A)2(124-A34-C)11(124-A34-A)2(124-A34-C)2(124-C34-C)124-C3(34-A124-A)35-3(A122-A36-)B122-A4(36-A122-B)5(36-A122-A)36-B6(122-A36-A)2(122-A36-C)13(122-A36-A)3(122-C36-A)2(122-A36-A)122-A37-3(A120-A38-)B120-A4(38-A120-B)5(38-A120-A)38-B3(120-C38-A)3(120-A38-A)2(120-A38-C)5(120-A38-A)6(120-B38-A)2(120-A38-A)3(120-C38-A)2(120-A38-A)120-A39-4(A118-A40-)2(A118-B40-)2(C118-B40-)3(C118-A40-)2(A118-A40-)3(A118-C40-)A118-A40-A118-B40-B118-A40-A2(118-A40-C)5(118-A40-A)6(118-B40-A)3(118-A40-B)4(118-A40-A)118-A41-6(A116-A42-)5(C116-A42-)2(A116-A42-)3(A116-C42-)A116-A42-A116-B2(42-A116-A)2(42-C116-A)4(42-A116-A)6(42-A116-B)42-A3(116-A42-B)4(116-A42-A)116-A43-6(A114-A44-)5(C114-A44-)2(A114-A44-)3(A114-C44-)A114-A44-A114-B6(44-A114-A)2(44-A114-C)44-B114-C44-B5(114-B44-A)3(114-A44-B)4(114-A44-A)114-A45-6(A112-A46-)5(C112-A46-)2(A112-A46-)3(A112-C46-)A112-A46-A112-B6(46-A112-A)2(46-A112-C)46-B112-C46-B5(112-A46-A)3(112-A46-B)4(112-A46-A)112-A47-24(A110-A48-)2(A110-C48-)B110-C48-B5(110-A48-A)3(110-A48-B)4(110-A48-A)110-A49-24(A108-A50-)3(A108-C50-)6(A108-A50-)3(B108-A50-)3(A108-A50-)A108-A51-6(A106-A52-)3(A106-C52-)10(A106-A52-)2(C106-A52-)3(A106-A52-)3(A106-C52-)12(A106-A52-)A106-A53-6(A104-A54-)3(A104-C54-)15(A104-A54-)3(A104-C54-)12(A104-A54-)A104-A55-6(A102-A56-)3(A102-C56-)3(A102-A56-)5(A102-B56-)7(A102-A56-)3(A102-C56-)12(A102-A56-)A102-A57-2(A100-A58-)3(C100-A58-)5(A100-A58-)2(B100-A58-)4(B100-B58-)A100-B7(58-A100-A)3(58-A100-C)13(58-A100-A)59-2(A98-A60-)3(C98-A60-)5(A98-A60-)2(B98-A60-)4(B98-B60-)A98-B15(60-A98-A)2(60-C98-A)2(60-C98-C)4(60-A98-A)61-2(A96-A62-)3(C96-A62-)27(A96-A62-)2(C96-A62-)2(C96-C62-)3(A96-A62-)A96-A63-2(A94-A64-)3(C94-A64-)17(A94-A64-)3(B94-A64-)7(A94-A64-)4(C94-A64-)3(A94-A64-)A94-A65-2(A92-A66-)3(C92-A66-)17(A92-A66-)3(B92-A66-)7(A92-A66-)4(C92-A66-)3(A92-A66-)A92-A67-2(A90-A68-)3(C90-A68-)16(A90-A68-)A3(90-C68-B)90-C15(68-A90-A)69-21(A88-A70-)4(A88-C70-)4(A88-A70-)3(A88-B70-)3(A88-A70-)B4(88-A70-A)88-A71-21(A86-A72-)4(A86-C72-)4(A86-A72-)3(A86-B72-)3(A86-A72-)B4(86-A72-A)86-A73-11(A84-A74-)2(A84-C74-)8(A84-A74-)4(A84-C74-)4(A84-A74-)3(A84-B74-)7(A84-A74-)A84-A75-9(A82-A76-)2(B82-A76-)2(B82-C76-)6(A82-A76-)4(C82-A76-)4(A82-A76-)2(B82-A76-)2(B82-B76-)A82-B8(76-A82-A)77-3(A80-A78-)2(A80-B78-)6(A80-A78-)2(A80-C78-)A80-A5(78-A80-B)78-C80-B3(78-C80-A)4(78-A80-A)4(78-B80-A)9(78-A80-A)79-3(A78-A80-)2(A78-B80-)9(A78-A80-)5(A78-B80-)C78-B3(80-C78-A)4(80-A78-A)4(80-B78-A)9(80-A78-A)81-3(A76-A82-)2(A76-B82-)9(A76-A82-)5(A76-B82-)C76-B3(82-C76-A)4(82-A76-A)4(82-B76-A)9(82-A76-A)83-14(A74-A84-)5(A74-B84-)C74-B3(84-C74-A)12(84-A74-A)2(84-B74-A)3(84-A74-A)85-14(A72-A86-)6(A72-B86-)15(A72-A86-)2(B72-A86-)2(A72-A86-)A72-A87-7(A70-A88-)2(B70-A88-)5(A70-A88-)6(A70-B88-)11(A70-A88-)2(A70-C88-)2(A70-A88-)2(B70-A88-)2(A70-A88-)A70-A89-7(A68-A90-)2(B68-A90-)15(A68-A90-)2(A68-C90-)5(A68-A90-)2(A68-C90-)2(A68-A90-)2(B68-A90-)2(A68-A90-)A68-A91-7(A66-A92-)2(B66-A92-)15(A66-A92-)2(2(A66-C92-)5(A66-A92-))A66-A92-A66-A93-7(A64-A94-)2(B64-A94-)22(A64-A94-)2(A64-B94-)6(A64-A94-)A64-A95-7(A62-A96-)2(B62-A96-)3(A62-A96-)4(C62-A96-)13(A62-A96-)2(B62-A96-)B2(62-B96-A)6(62-A96-A)62-A97-10(A60-A98-)2(A60-B98-)4(C60-B98-)13(A60-A98-)2(B60-A98-)B2(60-B98-A)6(60-A98-A)60-A49-
