model
name = poopy
revision = 8412
size = 23 40 21
origin = -y
shell = Outline 0.25
material type = toon, lighting = smooth, deform = 1 1
  colors = B:#FFDD21 C:#E8368F
material type = basic, lighting = smooth, roughness = 0, refractionRatio = 1, side = back
  colors = Outline:#000
voxels
69-B9(21-2B)5-2C7-2C5-13(2B21-)2B5-2C7-2C5-9(2B21-)B161-B14(21-2B)8-5B8-2B8C5-8C2B-22BC15(22B-)21B2-3(20B3-)20B70-B15(21-2B)8C5-8C2B-22BC15(22B-)21B2-3(20B3-)3(20B416-8C5-8C3-20B2-C19(20B3-))20B396-3C9-3C2(5-8C)7(3-20B2-C19(20B3-)20B396-3C9-3C5-21C)3-20B2-C19(20B3-)20B396-3C9-3C2(5-8C)3(3-20B2-C19(20B3-)20B416-8C5-8C)3-20B2-C19(20B3-)20B70-B15(21-2B)8C5-8C2B-22BC15(22B-)21B2-3(20B3-)20B70-B14(21-2B)8-5B8-2B8C5-8C2B-22BC15(22B-)21B2-3(20B3-)20B70-B9(21-2B)5-2C7-2C5-6(2B21-)2B16(-22B)-21B2-3(20B3-)20B-
