model
name = stairs
size = 80 40 40
scale = 0.05
origin = -y
shell = Outline 0.25
material type = toon, lighting = smooth, deform = 1 1
  colors = A:#FF9
material type = basic, lighting = smooth, roughness = 0, refractionRatio = 1, side = back
  colors = Outline:#000
voxels
80-80A3040-6320A80-3040A160-2960A240-2880A320-2800A400-2720A480-2640A560-2560A640-2480A720-2400A800-2320A880-2240A960-2160A1040-2080A1120-2000A1200-1920A1280-1840A1360-1760A1440-1680A1520-1600A1600-1520A1680-1440A1760-1360A1840-1280A1920-1200A2000-1120A2080-1040A2160-960A2240-880A2320-800A2400-720A2480-640A2560-560A2640-480A2720-400A2800-320A2880-240A2960-160A3040-
