model
name = wall
revision = 8461
size = 35 51 54
origin = -y
shell = Outline 0.25
material type = toon, lighting = smooth, deform = 1 1
  colors = B:#FFDD21
material type = basic, lighting = smooth, roughness = 0, refractionRatio = 1, side = back
  colors = Outline:#000
voxels
31228-8B5-7B15-5B-2B11-B19-4B33-B34-3(2B33-)2B31-2B34-2B1463-8B5-7B15-8B2(5-B)19-4B5(33-2B)31-2B33-B70-B139-B1254-8B5-7B15-5B-2B11-B15-8B2(11-B15-B5-2B)2(11-B21-2B)33-2B98-5B30-4B31-3B32-3B-B32-B-B34-B7-B1246-8B5-7B15-4B2-2B11-4(B34-)B341-4B34-B93-B1116-5B30-5B1745-2B33-2B1748-2B33-2B227-B34-B1485-2(5B30-5B189-B1555-)2B33-2B192-B438-B34-B1081-2B33-2B192-B400-2(B34-)B1084-2B33-2B192-B1555-2B33-2B192-7(B34-)B1310-2(2B33-)B34-2(2B33-)2B3(34-B)2(69-B)1363-2(2B33-)B34-2(2B33-)2B8(34-B)39715-
