model
name = walls
revision = 1
size = 80 40 80
origin = -y
shell = Outline 0.25
material type = toon, lighting = smooth, deform = 1 1
  colors = B:#EEE C:#555 D:#888 E:#777
material type = basic, lighting = smooth, roughness = 0, refractionRatio = 1, side = back
  colors = Outline:#000
voxels
-2B76-3B95(76-4B)76-3BE76-E2BE76-E3B13(76-4B)76-3BD76-D2BD76-D3B6(76-4B)76-3BD76-D3B2(76-4B)76-3BC76-C2BC76-C3B3(76-4B)76-3BD76-D2BD76-D3B2(76-4B)76-3BE76-E2BE76-E3B6(76-4B)76-3BC76-C2BC76-C3B4(76-4B)76-3BD76-D2BD76-D3B2(76-4B)76-2B160-2B5(76-4B)76-3BC76-C2BC76-C3B8(76-4B)76-3B2(E76-E2B)C76-C3B5(76-4B)76-3B2(C76-C2B)D76-D3B8(76-4B)76-2B160-2B17(76-4B)76-3BC76-C2BC76-C3B2(76-4B)76-3BD76-D2BD76-D3B2(76-4B)2(76-3BD76-D3B6(76-4B))24(76-4B)76-3BD76-D3B76-4B76-3BC76-C2BC76-C3B2(76-4B)76-3BD76-D3B5(76-4B)76-3BD76-D3B4(76-4B)76-3BD76-D3B2(76-4B)76-3B3(C76-C2B)C76-C3B13(76-4B)76-3BC76-C2BC76-C3B4(76-4B)76-2B160-2B2(76-4B)76-3BD76-D3B4(76-4B)76-3BD76-D3B2(76-4B)76-3B3(C76-C2B)C76-C3B7(76-4B)76-3BE76-E3B11(76-4B)76-2B160-2B18(76-4B)76-3BD76-D2BD76-D3B3(76-4B)76-3BE76-E3B32(76-4B)76-3BD76-D2BD76-D3B24(76-4B)76-3BC76-C2BC76-C3B3(76-4B)76-3BD76-D3B5(76-4B)76-3BD76-D2BD76-D3B13(76-4B)76-3BD76-D3B76-4B76-2B160-2B5(76-4B)76-3BC76-C2BC76-C3B15(76-4B)76-3BC76-C3B2(76-4B)76-3BD76-D2BD76-D3B7(76-4B)76-2B160-2B5(76-4B)76-3BC76-C2BC76-C3B76-4B76-3BD76-D3B12(76-4B)76-3BC76-C3B2(76-4B)76-3BD76-D2BD76-D3B23(76-4B)76-3BD76-D3B38(76-4B)76-3BD76-D3B22(76-4B)76-2B160-2B76-4B76-3BD76-D3B15(76-4B)76-3BC76-C2BC76-C3B10(76-4B)76-3BC76-C2BC76-C3B76-3BD76-D3B76-4B76-2B160-2B76-4B76-3BD76-D3B3(76-4B)76-3BD76-D2BD76-D3B15(76-4B)76-3BD76-D2BD76-D3B4(76-4B)76-3BC76-C2BC76-C3B76-3BD76-D3B10(76-4B)76-3BD76-D2BD76-D3B15(76-4B)76-3BD76-D2B2(D76-D3B76-4B76-3B)C76-C2BC76-C3B76-3BD76-D3B41(76-4B)76-2B160-2B10(76-4B)76-3BD76-D2BD76-D3B14(76-4B)76-3BD76-D2BD76-D3B7(76-4B)76-2B160-2B10(76-4B)76-3BD76-D2BD76-D3B3(76-4B)76-3BC76-C2BC76-C3B18(76-4B)76-2B160-2B6(76-4B)76-3BC76-C2BC76-C3B7(76-4B)76-3BC76-C2BC76-C3B3(76-4B)76-3B2(C76-C2B)C76-C3B11(76-4B)76-2B160-2B6(76-4B)76-3BC76-C2BC76-C3B7(76-4B)76-3BC76-C2BC76-C3B3(76-4B)76-3B2(C76-C2B)C76-C3B2(76-4B)76-3BD76-D3B11(76-4B)2(76-3BD76-D2BD76-D3B8(76-4B))5(76-4B)2(76-3BD76-D3B4(76-4B))76-4B76-3BD76-D2BD76-D3B8(76-4B)76-3BD76-D2BD76-D3B3(76-4B)76-3BC76-C2BC76-C3B7(76-4B)76-3BD76-D3B4(76-4B)76-3BD76-D3B76-4B76-2B160-2B34(76-4B)76-3BD76-D3B76-4B76-2B160-2B6(76-4B)76-3BD76-D3B23(76-4B)2(76-3BD76-D3B13(76-4B))4(76-4B)76-3BD76-D2BD76-D3B3(76-4B)76-3BD76-D3B13(76-4B)76-3BD76-D3B4(76-4B)2(76-3BD76-D2BD76-D3B5(76-4B))9(76-4B)76-2B160-2B6(76-4B)76-3BD76-D3B4(76-4B)76-3BD76-D2BD76-D3B22(76-4B)76-2B160-2B64(76-4B)76-3BE76-E3B3(76-4B)76-3B3(C76-C2B)C76-C3B20(76-4B)76-3BC76-C2BC76-C3B7(76-4B)76-3BE76-E3B3(76-4B)76-3B3(C76-C2B)C76-C3B3(76-4B)76-2B160-2B76-4B76-3BD76-D3B2(76-4B)76-3BC76-C2BC76-C3B6(76-4B)2(76-3BC76-C2BC76-C3B3(76-4B))3(76-4B)76-3B3(C76-C2B)C76-C3B3(76-4B)76-2B160-2B76-4B76-3BD76-D3B2(76-4B)76-3BC76-C2BC76-C3B2(76-4B)76-3BD76-D2BD76-D3B7(76-4B)76-3BC76-C2BC76-C3B6(76-4B)76-3B3(C76-C2B)C76-C3B7(76-4B)76-3BD76-D3B2(76-4B)76-3BC76-C2BC76-C3B2(76-4B)76-3BD76-D2BD76-D3B16(76-4B)76-3B3(C76-C2B)C76-C3B76-4B76-3BD76-D3B2(76-4B)76-2B-B76-B2-B76-B-BD76-D3B7(76-4B)76-3BD76-D2BD76-D3B3(76-4B)76-3BE76-E2BE76-E3B6(76-4B)76-3BC76-C2BC76-C3B7(76-4B)76-3BD76-D3B76-2B161-B76-B2-B76-B-2B14(76-4B)76-3BE76-E2BE76-E3B6(76-4B)76-3BC76-C2BC76-C3B7(76-4B)76-3BD76-D3B76-2B160-2B16(76-4B)76-3BE76-E2BE76-E3B117(76-4B)76-3BE76-E2BE76-E3B13(76-4B)76-3BD76-D2BD76-D3B6(76-4B)76-3BD76-D3B2(76-4B)76-3BC76-C2BC76-C3B3(76-4B)76-3BD76-D2BD76-D3B2(76-4B)76-3BE76-E2BE76-E3B6(76-4B)76-3BC76-C2BC76-C3B4(76-4B)76-3BD76-D2BD76-D3B2(76-4B)76-2B160-2B5(76-4B)76-3BC76-C2BC76-C3B8(76-4B)76-3B2(E76-E2B)C76-C3B5(76-4B)76-3B2(C76-C2B)D76-D3B8(76-4B)76-2B160-2B17(76-4B)76-3BC76-C2BC76-C3B2(76-4B)76-3BD76-D2BD76-D3B2(76-4B)2(76-3BD76-D3B6(76-4B))24(76-4B)76-3BD76-D3B76-4B76-3BC76-C2BC76-C3B2(76-4B)76-3BD76-D3B5(76-4B)76-3BD76-D3B4(76-4B)76-3BD76-D3B2(76-4B)76-3B3(C76-C2B)C76-C3B13(76-4B)76-3BC76-C2BC76-C3B4(76-4B)76-2B160-2B2(76-4B)76-3BD76-D3B4(76-4B)76-3BD76-D3B2(76-4B)76-3B3(C76-C2B)C76-C3B7(76-4B)76-3BE76-E3B11(76-4B)76-2B160-2B18(76-4B)76-3BD76-D2BD76-D3B3(76-4B)76-3BE76-E3B32(76-4B)76-3BD76-D2BD76-D3B24(76-4B)76-3BC76-C2BC76-C3B3(76-4B)76-3BD76-D3B5(76-4B)76-3BD76-D2BD76-D3B13(76-4B)76-3BD76-D3B76-4B76-2B160-2B5(76-4B)76-3BC76-C2BC76-C3B15(76-4B)76-3BC76-C3B2(76-4B)76-3BD76-D2BD76-D3B7(76-4B)76-2B160-2B5(76-4B)76-3BC76-C2BC76-C3B76-4B76-3BD76-D3B12(76-4B)76-3BC76-C3B2(76-4B)76-3BD76-D2BD76-D3B23(76-4B)76-3BD76-D3B38(76-4B)76-3BD76-D3B22(76-4B)76-2B160-2B76-4B76-3BD76-D3B15(76-4B)76-3BC76-C2BC76-C3B10(76-4B)76-3BC76-C2BC76-C3B76-3BD76-D3B76-4B76-2B160-2B76-4B76-3BD76-D3B3(76-4B)76-3BD76-D2BD76-D3B15(76-4B)76-3BD76-D2BD76-D3B4(76-4B)76-3BC76-C2BC76-C3B76-3BD76-D3B10(76-4B)76-3BD76-D2BD76-D3B15(76-4B)76-3BD76-D2B2(D76-D3B76-4B76-3B)C76-C2BC76-C3B76-3BD76-D3B41(76-4B)76-2B160-2B10(76-4B)76-3BD76-D2BD76-D3B14(76-4B)76-3BD76-D2BD76-D3B7(76-4B)76-2B160-2B10(76-4B)76-3BD76-D2BD76-D3B3(76-4B)76-3BC76-C2BC76-C3B18(76-4B)76-2B160-2B6(76-4B)76-3BC76-C2BC76-C3B7(76-4B)76-3BC76-C2BC76-C3B3(76-4B)76-3B2(C76-C2B)C76-C3B11(76-4B)76-2B160-2B6(76-4B)76-3BC76-C2BC76-C3B7(76-4B)76-3BC76-C2BC76-C3B3(76-4B)76-3B2(C76-C2B)C76-C3B2(76-4B)76-3BD76-D3B11(76-4B)2(76-3BD76-D2BD76-D3B8(76-4B))5(76-4B)2(76-3BD76-D3B4(76-4B))76-4B76-3BD76-D2BD76-D3B8(76-4B)76-3BD76-D2BD76-D3B3(76-4B)76-3BC76-C2BC76-C3B7(76-4B)76-3BD76-D3B4(76-4B)76-3BD76-D3B76-4B76-2B160-2B34(76-4B)76-3BD76-D3B76-4B76-2B160-2B6(76-4B)76-3BD76-D3B23(76-4B)2(76-3BD76-D3B13(76-4B))4(76-4B)76-3BD76-D2BD76-D3B3(76-4B)76-3BD76-D3B13(76-4B)76-3BD76-D3B4(76-4B)2(76-3BD76-D2BD76-D3B5(76-4B))9(76-4B)76-2B160-2B6(76-4B)76-3BD76-D3B4(76-4B)76-3BD76-D2BD76-D3B22(76-4B)76-2B160-2B64(76-4B)76-3BE76-E3B3(76-4B)76-3B3(C76-C2B)C76-C3B20(76-4B)76-3BC76-C2BC76-C3B7(76-4B)76-3BE76-E3B3(76-4B)76-3B3(C76-C2B)C76-C3B3(76-4B)76-2B160-2B76-4B76-3BD76-D3B2(76-4B)76-3BC76-C2BC76-C3B6(76-4B)2(76-3BC76-C2BC76-C3B3(76-4B))3(76-4B)76-3B3(C76-C2B)C76-C3B3(76-4B)76-2B160-2B76-4B76-3BD76-D3B2(76-4B)76-3BC76-C2BC76-C3B2(76-4B)76-3BD76-D2BD76-D3B7(76-4B)76-3BC76-C2BC76-C3B6(76-4B)76-3B3(C76-C2B)C76-C3B7(76-4B)76-3BD76-D3B2(76-4B)76-3BC76-C2BC76-C3B2(76-4B)76-3BD76-D2BD76-D3B16(76-4B)76-3B3(C76-C2B)C76-C3B76-4B76-3BD76-D3B2(76-4B)76-2B-B76-B2-B76-B-BD76-D3B7(76-4B)76-3BD76-D2BD76-D3B3(76-4B)76-3BE76-E2BE76-E3B6(76-4B)76-3BC76-C2BC76-C3B7(76-4B)76-3BD76-D3B76-2B161-B76-B2-B76-B-2B14(76-4B)76-3BE76-E2BE76-E3B6(76-4B)76-3BC76-C2BC76-C3B7(76-4B)76-3BD76-D3B76-2B160-2B16(76-4B)76-3BE76-E2BE76-E3B20(76-4B)76-2B
