model
name = wall
revision = 8402
size = 20 40 20
origin = -y
shell = Outline 0.25
material type = toon, lighting = smooth, deform = 1 1
  colors = B:#FFDD21
material type = basic, lighting = smooth, roughness = 0, refractionRatio = 1, side = back
  colors = Outline:#000
voxels
16(380-420B)380-3(339B4(-19B)381-)339B4(-19B)-
