model
name = wall
revision = 8424
size = 24 41 22
origin = -y
shell = Outline 0.25
material type = toon, lighting = smooth, deform = 1 1
  colors = B:#FFDD21
material type = basic, lighting = smooth, roughness = 0, refractionRatio = 1, side = back
  colors = Outline:#000
voxels
1466-2(20B4-)13B4(4-3B10-2B4-B)17-2B4-B11-13B11-7B7-B9-6(4B20-)7B7-B9-3(9B15-)9B495-2(20B4-)13B4(4-3B10-7B)17-7B11-13B11-6B7-2B6(9-6B8-B)9-15B9-3(9B15-)9B495-2(20B4-)13B4(4-3B4-B5-7B)2(11-B5-7B)11-B12-2B5(9-6B8-B)2(13-11B)13-2(5B19-)5B18-6B495-2(20B4-)2B6-7(5B4-3B4-B7-)12B5(4-2B12-6B)12-12B8-16B2(8-5B10-B)2(7-6B10-B)484-2(5B19-)2B22-4(B23-)3(B18-B4-)4(2B17-B4-)2(2B17-B23-3(B8-B14-)2(B7-2B14-)B484-2(5B19-)5(2B22-)7(2B17-B4-))2(2B17-B23-3(B8-B14-)2(B7-2B14-)B484-2(5B19-)4(2B22-)8(2B17-B4-))2B17-B23-3(B8-B14-)B7-2B14-B7-2B499-2(5B19-)4(2B22-)8(2B17-B4-)2B50-2(B23-)B2(14-B7-2B)3(499-2(5B19-)4(2B22-)8(2B17-B4-)2(2B22-)2(5B19-)2(5B14-B4-)5B)2(14-B484-2(5B19-)4(2B22-)8(2B17-B4-)2(2B22-)2(5B19-)2(5B14-B4-)5B)14-B647-7(B23-)B119-B23-B4-5B14-B647-9(B23-)B100-5B562-2(12(5B19-)5B18-6B18-5B77-9B558-)12(5B19-)5B18-6B18-5B77-8B998-
