model
name = wall
revision = 8454
size = 29 50 28
origin = -y
shell = Outline 0.25
material type = toon, lighting = smooth, deform = 1 1
  colors = B:#FFDD21
material type = basic, lighting = smooth, roughness = 0, refractionRatio = 1, side = back
  colors = Outline:#000
voxels
6501-8B5-7B9-5B-2B11-B13-4B27-B28-3(2B27-)2B25-2B28-2B225-2(4B25-)4B895-8B5-7B9-8B2(5-B)13-4B5(27-2B)25-2B27-B58-B115-B52-2(4B25-)4B895-8B5-7B9-5B-2B11-B9-8B2(11-B9-B5-2B)2(11-B15-2B)27-2B80-5B24-4B25-3B26-3B-B24-3B-B28-B7-B1001-8B5-7B9-4B2-2B11-4(B28-)B281-4B28-B75-B15-B28-B850-5B24-5B536-B28-B850-2B27-2B539-B28-B850-2B27-2B191-B28-B318-B28-B850-5B24-5B159-B405-B850-5B24-5B159-2(B360-B28-B866-2B27-2B162-)B328-2(B-2B25-)B-2B866-2B27-2B162-B1256-2B27-2B162-7(B28-)B1053-2(2B27-)B28-2(2B27-)2B3(28-B)2(57-B)1100-2(2B27-)B28-2(2B27-)2B8(28-B)13420-
