model
name = walls
size = 80 40 80
scale = 0.05
origin = -y
material type = toon, lighting = smooth, deform = 1 1 
  colors = A:#EEE B:#555 C:#888 D:#777
voxels
-4(2A2-)2A4-4(2A2-)4A4(2-2A)4-4(2A2-)3A2(3(2-38A)2-2918A2(4(2-2A)4-4(2A2-)4A))4(2-2A)4-4(2A2-)4A4(2-2A)4-4(2A2-)165A4C8A2C6A2C12AC5A4C8A2C6A2C12AC17A2C15A2C21A2C15A2C170A2(3B20A3B6A2B6A)3B3A4C3A2B3A2C3A3B6A2B6A3B3A4C3A2B3A2C3A3B6A2B19A2B3A2C33A2B3A2C48A2C38A2C33AC39AC15A2(3C13A2C22A)3C13A2C8AC7AC5A3C13A2C8AC7A2(C12A2C3A2C15A2B3A)C12A2C3A2C8A2C5A2B16A2C3A2C8A2C5A4(2B12A2B24A)2B7A2(3D13A3B16A3D2A)3D13A3B15AB3D2A3D13A3B15AB3D16A2(B8AB4A3C3A2B18A)B8AB4A3C23AB8AB4A3C13A3(2B4AC33A)2B4AC45A2(2B16AC21A)2B8A2B6AC21A2B8A2B6AC11A2D8A2B3A2C7A2D14A2D8A2B3A2C7A2D9A2(2B8AC9A2C12A2B4A)2B8AC23A2B4A2B8AC23A2B22AC6A2C5A3C23AC6A2C5A3C18A3C2ACAC4A2C26A3C2ACAC4A2C15A2(5B35A)2(5B24A2B9A)2(5B3A2C8A3B8A2B9A)5B13A3B12A2C5A5B13A3B12A2(2C38A)2C15A3C5A3C4AC24A3C5A3C4AC12A3C29A2C6A3C29A2C86A3(4(2-2A)4-4(2A2-)4A)4(2-2A)4-4(2A2-)2A243200-163A4C8A2C6A2C12AC5A4C8A2C6A2C12AC17A2C15A2C21A2C15A2C170A2(3B20A3B6A2B6A)3B3A4C3A2B3A2C3A3B6A2B6A3B3A4C3A2B3A2C3A3B6A2B19A2B3A2C33A2B3A2C48A2C38A2C33AC39AC15A2(3C13A2C22A)3C13A2C8AC7AC5A3C13A2C8AC7A2(C12A2C3A2C15A2B3A)C12A2C3A2C8A2C5A2B16A2C3A2C8A2C5A4(2B12A2B24A)2B7A2(3D13A3B16A3D2A)3D13A3B15AB3D2A3D13A3B15AB3D16A2(B8AB4A3C3A2B18A)B8AB4A3C23AB8AB4A3C13A3(2B4AC33A)2B4AC45A2(2B16AC21A)2B8A2B6AC21A2B8A2B6AC11A2D8A2B3A2C7A2D14A2D8A2B3A2C7A2D9A2(2B8AC9A2C12A2B4A)2B8AC23A2B4A2B8AC23A2B22AC6A2C5A3C23AC6A2C5A3C18A3C2ACAC4A2C26A3C2ACAC4A2C15A2(5B35A)2(5B24A2B9A)2(5B3A2C8A3B8A2B9A)5B13A3B12A2C5A5B13A3B12A2(2C38A)2C15A3C5A3C4AC24A3C5A3C4AC12A3C29A2C6A3C29A2C86A3(4(2-2A)4-4(2A2-)4A)4(2-2A)4-4(2A2-)2A
