model
name = walls
size = 80 40 80
scale = 0.05
origin = -y
shell = Outline 0.25
material type = toon, lighting = smooth, deform = 1 1
  colors = A:#EEE B:#555 C:#888 D:#777
material type = basic, lighting = smooth, roughness = 0, refractionRatio = 1, side = back
  colors = Outline:#000
voxels
-2A76-3A95(76-4A)76-3AD76-D2AD76-D3A13(76-4A)76-3AC76-C2AC76-C3A6(76-4A)76-3AC76-C3A2(76-4A)76-3AB76-B2AB76-B3A3(76-4A)76-3AC76-C2AC76-C3A2(76-4A)76-3AD76-D2AD76-D3A6(76-4A)76-3AB76-B2AB76-B3A4(76-4A)76-3AC76-C2AC76-C3A2(76-4A)76-2A160-2A5(76-4A)76-3AB76-B2AB76-B3A8(76-4A)76-3A2(D76-D2A)B76-B3A5(76-4A)76-3A2(B76-B2A)C76-C3A8(76-4A)76-2A160-2A17(76-4A)76-3AB76-B2AB76-B3A2(76-4A)76-3AC76-C2AC76-C3A2(76-4A)2(76-3AC76-C3A6(76-4A))24(76-4A)76-3AC76-C3A76-4A76-3AB76-B2AB76-B3A2(76-4A)76-3AC76-C3A5(76-4A)76-3AC76-C3A4(76-4A)76-3AC76-C3A2(76-4A)76-3A3(B76-B2A)B76-B3A13(76-4A)76-3AB76-B2AB76-B3A4(76-4A)76-2A160-2A2(76-4A)76-3AC76-C3A4(76-4A)76-3AC76-C3A2(76-4A)76-3A3(B76-B2A)B76-B3A7(76-4A)76-3AD76-D3A11(76-4A)76-2A160-2A18(76-4A)76-3AC76-C2AC76-C3A3(76-4A)76-3AD76-D3A32(76-4A)76-3AC76-C2AC76-C3A24(76-4A)76-3AB76-B2AB76-B3A3(76-4A)76-3AC76-C3A5(76-4A)76-3AC76-C2AC76-C3A13(76-4A)76-3AC76-C3A76-4A76-2A160-2A5(76-4A)76-3AB76-B2AB76-B3A15(76-4A)76-3AB76-B3A2(76-4A)76-3AC76-C2AC76-C3A7(76-4A)76-2A160-2A5(76-4A)76-3AB76-B2AB76-B3A76-4A76-3AC76-C3A12(76-4A)76-3AB76-B3A2(76-4A)76-3AC76-C2AC76-C3A23(76-4A)76-3AC76-C3A38(76-4A)76-3AC76-C3A22(76-4A)76-2A160-2A76-4A76-3AC76-C3A15(76-4A)76-3AB76-B2AB76-B3A10(76-4A)76-3AB76-B2AB76-B3A76-3AC76-C3A76-4A76-2A160-2A76-4A76-3AC76-C3A3(76-4A)76-3AC76-C2AC76-C3A15(76-4A)76-3AC76-C2AC76-C3A4(76-4A)76-3AB76-B2AB76-B3A76-3AC76-C3A10(76-4A)76-3AC76-C2AC76-C3A15(76-4A)76-3AC76-C2A2(C76-C3A76-4A76-3A)B76-B2AB76-B3A76-3AC76-C3A41(76-4A)76-2A160-2A10(76-4A)76-3AC76-C2AC76-C3A14(76-4A)76-3AC76-C2AC76-C3A7(76-4A)76-2A160-2A10(76-4A)76-3AC76-C2AC76-C3A3(76-4A)76-3AB76-B2AB76-B3A18(76-4A)76-2A160-2A6(76-4A)76-3AB76-B2AB76-B3A7(76-4A)76-3AB76-B2AB76-B3A3(76-4A)76-3A2(B76-B2A)B76-B3A11(76-4A)76-2A160-2A6(76-4A)76-3AB76-B2AB76-B3A7(76-4A)76-3AB76-B2AB76-B3A3(76-4A)76-3A2(B76-B2A)B76-B3A2(76-4A)76-3AC76-C3A11(76-4A)2(76-3AC76-C2AC76-C3A8(76-4A))5(76-4A)2(76-3AC76-C3A4(76-4A))76-4A76-3AC76-C2AC76-C3A8(76-4A)76-3AC76-C2AC76-C3A3(76-4A)76-3AB76-B2AB76-B3A7(76-4A)76-3AC76-C3A4(76-4A)76-3AC76-C3A76-4A76-2A160-2A34(76-4A)76-3AC76-C3A76-4A76-2A160-2A6(76-4A)76-3AC76-C3A23(76-4A)2(76-3AC76-C3A13(76-4A))4(76-4A)76-3AC76-C2AC76-C3A3(76-4A)76-3AC76-C3A13(76-4A)76-3AC76-C3A4(76-4A)2(76-3AC76-C2AC76-C3A5(76-4A))9(76-4A)76-2A160-2A6(76-4A)76-3AC76-C3A4(76-4A)76-3AC76-C2AC76-C3A22(76-4A)76-2A160-2A64(76-4A)76-3AD76-D3A3(76-4A)76-3A3(B76-B2A)B76-B3A20(76-4A)76-3AB76-B2AB76-B3A7(76-4A)76-3AD76-D3A3(76-4A)76-3A3(B76-B2A)B76-B3A3(76-4A)76-2A160-2A76-4A76-3AC76-C3A2(76-4A)76-3AB76-B2AB76-B3A6(76-4A)2(76-3AB76-B2AB76-B3A3(76-4A))3(76-4A)76-3A3(B76-B2A)B76-B3A3(76-4A)76-2A160-2A76-4A76-3AC76-C3A2(76-4A)76-3AB76-B2AB76-B3A2(76-4A)76-3AC76-C2AC76-C3A7(76-4A)76-3AB76-B2AB76-B3A6(76-4A)76-3A3(B76-B2A)B76-B3A7(76-4A)76-3AC76-C3A2(76-4A)76-3AB76-B2AB76-B3A2(76-4A)76-3AC76-C2AC76-C3A16(76-4A)76-3A3(B76-B2A)B76-B3A76-4A76-3AC76-C3A2(76-4A)76-2A-A76-A2-A76-A-AC76-C3A7(76-4A)76-3AC76-C2AC76-C3A3(76-4A)76-3AD76-D2AD76-D3A6(76-4A)76-3AB76-B2AB76-B3A7(76-4A)76-3AC76-C3A76-2A161-A76-A2-A76-A-2A14(76-4A)76-3AD76-D2AD76-D3A6(76-4A)76-3AB76-B2AB76-B3A7(76-4A)76-3AC76-C3A76-2A160-2A16(76-4A)76-3AD76-D2AD76-D3A117(76-4A)76-3AD76-D2AD76-D3A13(76-4A)76-3AC76-C2AC76-C3A6(76-4A)76-3AC76-C3A2(76-4A)76-3AB76-B2AB76-B3A3(76-4A)76-3AC76-C2AC76-C3A2(76-4A)76-3AD76-D2AD76-D3A6(76-4A)76-3AB76-B2AB76-B3A4(76-4A)76-3AC76-C2AC76-C3A2(76-4A)76-2A160-2A5(76-4A)76-3AB76-B2AB76-B3A8(76-4A)76-3A2(D76-D2A)B76-B3A5(76-4A)76-3A2(B76-B2A)C76-C3A8(76-4A)76-2A160-2A17(76-4A)76-3AB76-B2AB76-B3A2(76-4A)76-3AC76-C2AC76-C3A2(76-4A)2(76-3AC76-C3A6(76-4A))24(76-4A)76-3AC76-C3A76-4A76-3AB76-B2AB76-B3A2(76-4A)76-3AC76-C3A5(76-4A)76-3AC76-C3A4(76-4A)76-3AC76-C3A2(76-4A)76-3A3(B76-B2A)B76-B3A13(76-4A)76-3AB76-B2AB76-B3A4(76-4A)76-2A160-2A2(76-4A)76-3AC76-C3A4(76-4A)76-3AC76-C3A2(76-4A)76-3A3(B76-B2A)B76-B3A7(76-4A)76-3AD76-D3A11(76-4A)76-2A160-2A18(76-4A)76-3AC76-C2AC76-C3A3(76-4A)76-3AD76-D3A32(76-4A)76-3AC76-C2AC76-C3A24(76-4A)76-3AB76-B2AB76-B3A3(76-4A)76-3AC76-C3A5(76-4A)76-3AC76-C2AC76-C3A13(76-4A)76-3AC76-C3A76-4A76-2A160-2A5(76-4A)76-3AB76-B2AB76-B3A15(76-4A)76-3AB76-B3A2(76-4A)76-3AC76-C2AC76-C3A7(76-4A)76-2A160-2A5(76-4A)76-3AB76-B2AB76-B3A76-4A76-3AC76-C3A12(76-4A)76-3AB76-B3A2(76-4A)76-3AC76-C2AC76-C3A23(76-4A)76-3AC76-C3A38(76-4A)76-3AC76-C3A22(76-4A)76-2A160-2A76-4A76-3AC76-C3A15(76-4A)76-3AB76-B2AB76-B3A10(76-4A)76-3AB76-B2AB76-B3A76-3AC76-C3A76-4A76-2A160-2A76-4A76-3AC76-C3A3(76-4A)76-3AC76-C2AC76-C3A15(76-4A)76-3AC76-C2AC76-C3A4(76-4A)76-3AB76-B2AB76-B3A76-3AC76-C3A10(76-4A)76-3AC76-C2AC76-C3A15(76-4A)76-3AC76-C2A2(C76-C3A76-4A76-3A)B76-B2AB76-B3A76-3AC76-C3A41(76-4A)76-2A160-2A10(76-4A)76-3AC76-C2AC76-C3A14(76-4A)76-3AC76-C2AC76-C3A7(76-4A)76-2A160-2A10(76-4A)76-3AC76-C2AC76-C3A3(76-4A)76-3AB76-B2AB76-B3A18(76-4A)76-2A160-2A6(76-4A)76-3AB76-B2AB76-B3A7(76-4A)76-3AB76-B2AB76-B3A3(76-4A)76-3A2(B76-B2A)B76-B3A11(76-4A)76-2A160-2A6(76-4A)76-3AB76-B2AB76-B3A7(76-4A)76-3AB76-B2AB76-B3A3(76-4A)76-3A2(B76-B2A)B76-B3A2(76-4A)76-3AC76-C3A11(76-4A)2(76-3AC76-C2AC76-C3A8(76-4A))5(76-4A)2(76-3AC76-C3A4(76-4A))76-4A76-3AC76-C2AC76-C3A8(76-4A)76-3AC76-C2AC76-C3A3(76-4A)76-3AB76-B2AB76-B3A7(76-4A)76-3AC76-C3A4(76-4A)76-3AC76-C3A76-4A76-2A160-2A34(76-4A)76-3AC76-C3A76-4A76-2A160-2A6(76-4A)76-3AC76-C3A23(76-4A)2(76-3AC76-C3A13(76-4A))4(76-4A)76-3AC76-C2AC76-C3A3(76-4A)76-3AC76-C3A13(76-4A)76-3AC76-C3A4(76-4A)2(76-3AC76-C2AC76-C3A5(76-4A))9(76-4A)76-2A160-2A6(76-4A)76-3AC76-C3A4(76-4A)76-3AC76-C2AC76-C3A22(76-4A)76-2A160-2A64(76-4A)76-3AD76-D3A3(76-4A)76-3A3(B76-B2A)B76-B3A20(76-4A)76-3AB76-B2AB76-B3A7(76-4A)76-3AD76-D3A3(76-4A)76-3A3(B76-B2A)B76-B3A3(76-4A)76-2A160-2A76-4A76-3AC76-C3A2(76-4A)76-3AB76-B2AB76-B3A6(76-4A)2(76-3AB76-B2AB76-B3A3(76-4A))3(76-4A)76-3A3(B76-B2A)B76-B3A3(76-4A)76-2A160-2A76-4A76-3AC76-C3A2(76-4A)76-3AB76-B2AB76-B3A2(76-4A)76-3AC76-C2AC76-C3A7(76-4A)76-3AB76-B2AB76-B3A6(76-4A)76-3A3(B76-B2A)B76-B3A7(76-4A)76-3AC76-C3A2(76-4A)76-3AB76-B2AB76-B3A2(76-4A)76-3AC76-C2AC76-C3A16(76-4A)76-3A3(B76-B2A)B76-B3A76-4A76-3AC76-C3A2(76-4A)76-2A-A76-A2-A76-A-AC76-C3A7(76-4A)76-3AC76-C2AC76-C3A3(76-4A)76-3AD76-D2AD76-D3A6(76-4A)76-3AB76-B2AB76-B3A7(76-4A)76-3AC76-C3A76-2A161-A76-A2-A76-A-2A14(76-4A)76-3AD76-D2AD76-D3A6(76-4A)76-3AB76-B2AB76-B3A7(76-4A)76-3AC76-C3A76-2A160-2A16(76-4A)76-3AD76-D2AD76-D3A20(76-4A)76-2A
