model
name = wall
revision = 8403
size = 20 41 21
origin = -y
shell = Outline 0.25
material type = toon, lighting = smooth, deform = 1 1
  colors = B:#FFDD21
material type = basic, lighting = smooth, roughness = 0, refractionRatio = 1, side = back
  colors = Outline:#000
voxels
1220-16(420B400-)3(339B4(-19B)401-)339B2(-19B)-8B-B2(-8B)-B-8B-
