model
name = wall
revision = 8432
size = 24 41 22
origin = -y
shell = Outline 0.25
material type = toon, lighting = smooth, deform = 1 1
  colors = B:#FFDD21
material type = basic, lighting = smooth, roughness = 0, refractionRatio = 1, side = back
  colors = Outline:#000
voxels
1466-2(20B4-)13B4(4-3B10-2B4-B)17-2B4-B11-13B11-7B7-B9-6(4B20-)4B10-B9-2(4B20-)4B524-2(20B4-)13B4(4-3B10-7B)17-7B11-13B11-6B7-2B6(9-6B8-B)9-4B7-4B9-2(4B20-)4B524-2(20B4-)13B4(4-3B4-B5-7B)2(11-B5-7B)11-B12-2B5(9-6B8-B)13-11B20-4B585-2(20B4-)2B6-7(5B4-3B4-B7-)12B5(4-2B12-6B)12-12B15-9B2(23-B)7-B15-B23-B484-2(5B19-)2B22-4(B23-)3(B18-B4-)3(2B17-B4-)2(2B17-7(B23-)B484-7(2B22-)6(2B17-B4-))2B17-7(B23-)B484-2(5B19-)4(2B22-)7(2B17-B4-)2B17-7(B23-)B484-2(5B19-)2B22-3(B23-)8(B18-B4-)B18-4(B23-)B7-B15-B7-B500-2(5B19-)2B22-3(B23-)8(B18-B4-)B114-B7-B15-B7-B500-2(5B19-)2B22-3(B23-)8(B18-B4-)2(B23-)2(B-2B20-)2(B-2B15-B4-)B-2B500-2(5B19-)4(2B22-)7(2B17-B4-)2B17-B119-B23-B508-2(6(2B22-)7(2B17-B4-)2B17-B119-2(B23-)B484-)2(5B19-)4(2B22-)7(2B17-B4-)2B17-2(B119-2(B23-)B647-7(B23-))2(B23-)B667-2(12(5B19-)5B18-6B18-5B644-)12(5B19-)5B18-6B18-5B1083-
