model
name = wall
revision = 8411
size = 24 41 22
origin = -y
shell = Outline 0.25
material type = toon, lighting = smooth, deform = 1 1
  colors = B:#FFDD21
material type = basic, lighting = smooth, roughness = 0, refractionRatio = 1, side = back
  colors = Outline:#000
voxels
1466-2(2(20B4-)20B5(10-14B)13(4-20B)484-)3(20B4-)7(B5-14B4-)10(20B4-)20B484-2(20B4-)2B6-7(12B4-B7-)6(12B4-2B6-)12B5(4-20B)484-2(5B19-)2B22-4(B23-)3(B18-B4-)6(2B17-B4-)2(4(5B14-B4-)5B14-B484-2(5B19-)5(2B22-)9(2B17-B4-))2(4(5B14-B4-)5B14-B484-2(5B19-)4(2B22-)10(2B17-B4-))4(5B14-B4-)4(5B499-2(5B19-)4(2B22-)8(2B17-B4-)2(2B22-)2(5B19-)2(5B14-B4-))2(5B14-B484-2(5B19-)4(2B22-)8(2B17-B4-)2(2B22-)2(5B19-)2(5B14-B4-))5B14-B647-7(B23-)B119-B23-B4-5B14-B647-9(B23-)B100-5B562-2(12(5B19-)5B18-6B18-3(5B19-)5B5-19B548-)12(5B19-)5B18-6B18-3(5B19-)5B5-8B-B-8B987-
