model
name = wall
revision = 8437
size = 24 41 22
origin = -y
shell = Outline 0.25
material type = toon, lighting = smooth, deform = 1 1
  colors = B:#FFDD21
material type = basic, lighting = smooth, roughness = 0, refractionRatio = 1, side = back
  colors = Outline:#000
voxels
1466-20B4-20B8-9B5(17-2B4-B)15-9B15-3B7-B177-2(4B20-)4B524-20B4-20B8-9B5(17-7B)15-9B15-2B7-2B5(13-2B8-B)14-B29-3B10-2(4B20-)4B524-2(20B4-)13B3(4-3B4-B5-7B)4-3B10-2(7B17-)7B24-2B5(10-5B8-B)13-11B20-4B585-2(20B4-)2B6-3(5B4-3B4-B7-)5B4-3B12-3(5B4-B14-)10B5(7-B12-4B)14-10B17-7B25-B23-B7-B15-B23-B484-2(5B19-)2B22-2(B23-)B120-3(B23-)B113-3(B23-)B484-5(2B22-)2B8(23-B)113-3(B23-)B484-7(2B22-)6(2B17-B4-)2B17-7(B23-)B484-2(5B19-)4(2B22-)2B17-B4-6(2B22-)2B185-B484-2(2(5B19-)2B22-3(B23-)B18-B4-7(B23-)B122-B23-B500-)2(5B19-)2B22-3(B23-)B18-B4-9(B23-)4(B-2B20-)B-2B500-2(5B19-)4(2B22-)2B17-B4-6(2B22-)2B670-6(2B22-)7(2B17-B4-)2B17-B119-2(B23-)B484-5(2B22-)2B8(23-B)137-2(B23-)B484-2(5B19-)3(2B22-)2B8(23-B)137-2(B23-)B935-2(B23-)B4922-
