model
name = wall
revision = 8439
size = 29 41 23
origin = -y
shell = Outline 0.25
material type = toon, lighting = smooth, deform = 1 1
  colors = B:#FFDD21
material type = basic, lighting = smooth, roughness = 0, refractionRatio = 1, side = back
  colors = Outline:#000
voxels
2963-20B9-5B-7B-6B13-9B22-B5-4(B22-2B4-)B20-2B28-2B225-2(4B25-)4B634-20B9-20B13-9B5(22-7B)20-2B27-B9-B48-B115-B52-2(4B25-)4B634-20B9-5B-7B-6B9-13B2(4-3B9-B5-7B)4-3B15-7B4-B-B15-7B22-7B58-B16-5B8-B15-4B9-B15-3B26-3B-B24-3B-B28-B7-B740-20B9-4B2-7B2-5B9-2B6-3(5B4-3B9-B7-)5B4-3B17-2(5B4-B19-)5B4-B20-B2-3B-2B12-B12-4B2(2(12-B)-2B)2(12-B12-4B)22-7B25-4B30-B28-B12-B15-B28-B589-2(5B24-)3(B28-)B145-3(B28-)B133-3(B28-)B589-2(2B27-)B28-2(2B27-)2B3(28-B)2(57-B)162-3(B28-)B589-7(2B27-)2B17-3(B9-B18-)B9-2B17-2(B9-B18-)7(B28-)B589-2(5B24-)2B27-B28-2(2B27-)2B17-B9-4(B28-)2(2B27-)B221-B589-2(5B24-)2B27-B57-B47-B9-7(B28-)B147-B28-B605-2(5B24-)2B27-B28-B76-B9-2(B57-)3(B28-)B147-B28-B605-2(5B24-)2B27-B57-B47-B9-9(B28-)4(B-2B25-)B-2B605-2(5B24-)2B27-B28-2(2B27-)2B17-B9-4(B28-)2(2B27-)B811-6(2B27-)2(2B17-B9-)3(B18-B9-)2B17-2(B9-B18-)B144-2(B28-)B589-2(2B27-)B28-2(2B27-)2B3(28-B)2(57-B)191-2(B28-)B589-2(5B24-)B28-2(2B27-)2B8(28-B)162-2(B28-)B1130-2(B28-)B5949-
